<?xml version="1.0" encoding="UTF-8"?>
<!-- Generated by org.testng.reporters.JUnitReportReporter -->
<testsuite skipped="0" hostname="WTC-5159473-l2" name="USRC.USRC_General" tests="5" failures="5" timestamp="28 Dec 2018 20:56:23 GMT" time="4.892" errors="0">
  <testcase name="CreateUsers" time="0.805" classname="USRC.USRC_General">
    <failure type="java.lang.AssertionError" message="
Expected: a string containing &quot;successful\&quot;:true&quot;
     but: was &quot;{&quot;successful&quot;:false,&quot;errorList&quot;:[{&quot;code&quot;:&quot;PSWD_LENGTH_INVALID&quot;,&quot;message&quot;:&quot;We were unable to process your request. Please try again.&quot;,&quot;contextList&quot;:[&quot;SENDER&quot;],&quot;source&quot;:&quot;WERL&quot;}]}&quot;">
      <![CDATA[java.lang.AssertionError: 
Expected: a string containing "successful\":true"
     but: was "{"successful":false,"errorList":[{"code":"PSWD_LENGTH_INVALID","message":"We were unable to process your request. Please try again.","contextList":["SENDER"],"source":"WERL"}]}"
at org.hamcrest.MatcherAssert.assertThat(MatcherAssert.java:20)
at org.junit.Assert.assertThat(Assert.java:956)
at org.junit.Assert.assertThat(Assert.java:923)
at USRC.USRC_General.CreateUsers(USRC_General.java:63)
at sun.reflect.NativeMethodAccessorImpl.invoke0(Native Method)
at sun.reflect.NativeMethodAccessorImpl.invoke(Unknown Source)
at sun.reflect.DelegatingMethodAccessorImpl.invoke(Unknown Source)
at java.lang.reflect.Method.invoke(Unknown Source)
at org.testng.internal.MethodInvocationHelper.invokeMethod(MethodInvocationHelper.java:124)
at org.testng.internal.Invoker.invokeMethod(Invoker.java:580)
at org.testng.internal.Invoker.invokeTestMethod(Invoker.java:716)
at org.testng.internal.TestMethodWithDataProviderMethodWorker.call(TestMethodWithDataProviderMethodWorker.java:71)
at org.testng.internal.TestMethodWithDataProviderMethodWorker.call(TestMethodWithDataProviderMethodWorker.java:14)
at java.util.concurrent.FutureTask.run(Unknown Source)
at java.util.concurrent.Executors$RunnableAdapter.call(Unknown Source)
at java.util.concurrent.FutureTask.run(Unknown Source)
at java.util.concurrent.ThreadPoolExecutor.runWorker(Unknown Source)
at java.util.concurrent.ThreadPoolExecutor$Worker.run(Unknown Source)
at java.lang.Thread.run(Unknown Source)
]]>
    </failure>
  </testcase> <!-- CreateUsers -->
  <testcase name="CreateUsers" time="0.974" classname="USRC.USRC_General">
    <failure type="java.lang.AssertionError" message="
Expected: a string containing &quot;successful\&quot;:true&quot;
     but: was &quot;{&quot;successful&quot;:false,&quot;errorList&quot;:[{&quot;code&quot;:&quot;PSWD_LENGTH_INVALID&quot;,&quot;message&quot;:&quot;We were unable to process your request. Please try again.&quot;,&quot;contextList&quot;:[&quot;SENDER&quot;],&quot;source&quot;:&quot;WERL&quot;}]}&quot;">
      <![CDATA[java.lang.AssertionError: 
Expected: a string containing "successful\":true"
     but: was "{"successful":false,"errorList":[{"code":"PSWD_LENGTH_INVALID","message":"We were unable to process your request. Please try again.","contextList":["SENDER"],"source":"WERL"}]}"
at org.hamcrest.MatcherAssert.assertThat(MatcherAssert.java:20)
at org.junit.Assert.assertThat(Assert.java:956)
at org.junit.Assert.assertThat(Assert.java:923)
at USRC.USRC_General.CreateUsers(USRC_General.java:63)
at sun.reflect.NativeMethodAccessorImpl.invoke0(Native Method)
at sun.reflect.NativeMethodAccessorImpl.invoke(Unknown Source)
at sun.reflect.DelegatingMethodAccessorImpl.invoke(Unknown Source)
at java.lang.reflect.Method.invoke(Unknown Source)
at org.testng.internal.MethodInvocationHelper.invokeMethod(MethodInvocationHelper.java:124)
at org.testng.internal.Invoker.invokeMethod(Invoker.java:580)
at org.testng.internal.Invoker.invokeTestMethod(Invoker.java:716)
at org.testng.internal.TestMethodWithDataProviderMethodWorker.call(TestMethodWithDataProviderMethodWorker.java:71)
at org.testng.internal.TestMethodWithDataProviderMethodWorker.call(TestMethodWithDataProviderMethodWorker.java:14)
at java.util.concurrent.FutureTask.run(Unknown Source)
at java.util.concurrent.Executors$RunnableAdapter.call(Unknown Source)
at java.util.concurrent.FutureTask.run(Unknown Source)
at java.util.concurrent.ThreadPoolExecutor.runWorker(Unknown Source)
at java.util.concurrent.ThreadPoolExecutor$Worker.run(Unknown Source)
at java.lang.Thread.run(Unknown Source)
]]>
    </failure>
  </testcase> <!-- CreateUsers -->
  <testcase name="CreateUsers" time="1.149" classname="USRC.USRC_General">
    <failure type="java.lang.AssertionError" message="
Expected: a string containing &quot;successful\&quot;:true&quot;
     but: was &quot;{&quot;successful&quot;:false,&quot;errorList&quot;:[{&quot;code&quot;:&quot;PSWD_LENGTH_INVALID&quot;,&quot;message&quot;:&quot;We were unable to process your request. Please try again.&quot;,&quot;contextList&quot;:[&quot;SENDER&quot;],&quot;source&quot;:&quot;WERL&quot;}]}&quot;">
      <![CDATA[java.lang.AssertionError: 
Expected: a string containing "successful\":true"
     but: was "{"successful":false,"errorList":[{"code":"PSWD_LENGTH_INVALID","message":"We were unable to process your request. Please try again.","contextList":["SENDER"],"source":"WERL"}]}"
at org.hamcrest.MatcherAssert.assertThat(MatcherAssert.java:20)
at org.junit.Assert.assertThat(Assert.java:956)
at org.junit.Assert.assertThat(Assert.java:923)
at USRC.USRC_General.CreateUsers(USRC_General.java:63)
at sun.reflect.NativeMethodAccessorImpl.invoke0(Native Method)
at sun.reflect.NativeMethodAccessorImpl.invoke(Unknown Source)
at sun.reflect.DelegatingMethodAccessorImpl.invoke(Unknown Source)
at java.lang.reflect.Method.invoke(Unknown Source)
at org.testng.internal.MethodInvocationHelper.invokeMethod(MethodInvocationHelper.java:124)
at org.testng.internal.Invoker.invokeMethod(Invoker.java:580)
at org.testng.internal.Invoker.invokeTestMethod(Invoker.java:716)
at org.testng.internal.TestMethodWithDataProviderMethodWorker.call(TestMethodWithDataProviderMethodWorker.java:71)
at org.testng.internal.TestMethodWithDataProviderMethodWorker.call(TestMethodWithDataProviderMethodWorker.java:14)
at java.util.concurrent.FutureTask.run(Unknown Source)
at java.util.concurrent.Executors$RunnableAdapter.call(Unknown Source)
at java.util.concurrent.FutureTask.run(Unknown Source)
at java.util.concurrent.ThreadPoolExecutor.runWorker(Unknown Source)
at java.util.concurrent.ThreadPoolExecutor$Worker.run(Unknown Source)
at java.lang.Thread.run(Unknown Source)
]]>
    </failure>
  </testcase> <!-- CreateUsers -->
  <testcase name="CreateUsers" time="0.680" classname="USRC.USRC_General">
    <failure type="java.lang.AssertionError" message="
Expected: a string containing &quot;successful\&quot;:true&quot;
     but: was &quot;{&quot;successful&quot;:false,&quot;errorList&quot;:[{&quot;code&quot;:&quot;PSWD_LENGTH_INVALID&quot;,&quot;message&quot;:&quot;We were unable to process your request. Please try again.&quot;,&quot;contextList&quot;:[&quot;SENDER&quot;],&quot;source&quot;:&quot;WERL&quot;}]}&quot;">
      <![CDATA[java.lang.AssertionError: 
Expected: a string containing "successful\":true"
     but: was "{"successful":false,"errorList":[{"code":"PSWD_LENGTH_INVALID","message":"We were unable to process your request. Please try again.","contextList":["SENDER"],"source":"WERL"}]}"
at org.hamcrest.MatcherAssert.assertThat(MatcherAssert.java:20)
at org.junit.Assert.assertThat(Assert.java:956)
at org.junit.Assert.assertThat(Assert.java:923)
at USRC.USRC_General.CreateUsers(USRC_General.java:63)
at sun.reflect.NativeMethodAccessorImpl.invoke0(Native Method)
at sun.reflect.NativeMethodAccessorImpl.invoke(Unknown Source)
at sun.reflect.DelegatingMethodAccessorImpl.invoke(Unknown Source)
at java.lang.reflect.Method.invoke(Unknown Source)
at org.testng.internal.MethodInvocationHelper.invokeMethod(MethodInvocationHelper.java:124)
at org.testng.internal.Invoker.invokeMethod(Invoker.java:580)
at org.testng.internal.Invoker.invokeTestMethod(Invoker.java:716)
at org.testng.internal.TestMethodWithDataProviderMethodWorker.call(TestMethodWithDataProviderMethodWorker.java:71)
at org.testng.internal.TestMethodWithDataProviderMethodWorker.call(TestMethodWithDataProviderMethodWorker.java:14)
at java.util.concurrent.FutureTask.run(Unknown Source)
at java.util.concurrent.Executors$RunnableAdapter.call(Unknown Source)
at java.util.concurrent.FutureTask.run(Unknown Source)
at java.util.concurrent.ThreadPoolExecutor.runWorker(Unknown Source)
at java.util.concurrent.ThreadPoolExecutor$Worker.run(Unknown Source)
at java.lang.Thread.run(Unknown Source)
]]>
    </failure>
  </testcase> <!-- CreateUsers -->
  <testcase name="CreateUsers" time="1.284" classname="USRC.USRC_General">
    <failure type="java.lang.AssertionError" message="
Expected: a string containing &quot;successful\&quot;:true&quot;
     but: was &quot;{&quot;successful&quot;:false,&quot;errorList&quot;:[{&quot;code&quot;:&quot;PSWD_LENGTH_INVALID&quot;,&quot;message&quot;:&quot;We were unable to process your request. Please try again.&quot;,&quot;contextList&quot;:[&quot;SENDER&quot;],&quot;source&quot;:&quot;WERL&quot;}]}&quot;">
      <![CDATA[java.lang.AssertionError: 
Expected: a string containing "successful\":true"
     but: was "{"successful":false,"errorList":[{"code":"PSWD_LENGTH_INVALID","message":"We were unable to process your request. Please try again.","contextList":["SENDER"],"source":"WERL"}]}"
at org.hamcrest.MatcherAssert.assertThat(MatcherAssert.java:20)
at org.junit.Assert.assertThat(Assert.java:956)
at org.junit.Assert.assertThat(Assert.java:923)
at USRC.USRC_General.CreateUsers(USRC_General.java:63)
at sun.reflect.NativeMethodAccessorImpl.invoke0(Native Method)
at sun.reflect.NativeMethodAccessorImpl.invoke(Unknown Source)
at sun.reflect.DelegatingMethodAccessorImpl.invoke(Unknown Source)
at java.lang.reflect.Method.invoke(Unknown Source)
at org.testng.internal.MethodInvocationHelper.invokeMethod(MethodInvocationHelper.java:124)
at org.testng.internal.Invoker.invokeMethod(Invoker.java:580)
at org.testng.internal.Invoker.invokeTestMethod(Invoker.java:716)
at org.testng.internal.TestMethodWithDataProviderMethodWorker.call(TestMethodWithDataProviderMethodWorker.java:71)
at org.testng.internal.TestMethodWithDataProviderMethodWorker.call(TestMethodWithDataProviderMethodWorker.java:14)
at java.util.concurrent.FutureTask.run(Unknown Source)
at java.util.concurrent.Executors$RunnableAdapter.call(Unknown Source)
at java.util.concurrent.FutureTask.run(Unknown Source)
at java.util.concurrent.ThreadPoolExecutor.runWorker(Unknown Source)
at java.util.concurrent.ThreadPoolExecutor$Worker.run(Unknown Source)
at java.lang.Thread.run(Unknown Source)
]]>
    </failure>
  </testcase> <!-- CreateUsers -->
</testsuite> <!-- USRC.USRC_General -->
