<?xml version="1.0" encoding="UTF-8"?>
<!-- Generated by org.testng.reporters.JUnitReportReporter -->
<testsuite skipped="5" hostname="WTC-5159473-l2" name="TestNG.MFAC" tests="30" failures="5" timestamp="25 Oct 2018 18:14:14 GMT" time="346.952" errors="0">
  <testcase name="testMethod" time="0.012" classname="TestNG.MFAC"/>
  <testcase name="IssuePin" time="2.035" classname="TestNG.MFAC"/>
  <testcase name="IssuePin" time="1.631" classname="TestNG.MFAC"/>
  <testcase name="VerifyPinVelocity" time="22.002" classname="TestNG.MFAC"/>
  <testcase name="VerifyPinNoLongerValid" time="13.658" classname="TestNG.MFAC"/>
  <testcase name="AddressVelocity" time="34.229" classname="TestNG.MFAC">
    <failure type="java.lang.AssertionError" message="
Expected: (a string containing &quot;DENY&quot; and a string containing &quot;Unfortunately, too many failed attempts for registration have occurred. Please try again later.&quot;)
     but: a string containing &quot;DENY&quot; was &quot;{&quot;transactionId&quot;:&quot;4e087e65-77b9-4575-9965-afaaf214e968&quot;,&quot;output&quot;:{&quot;advice&quot;:&quot;ALLOW&quot;}}&quot;">
      <![CDATA[java.lang.AssertionError: 
Expected: (a string containing "DENY" and a string containing "Unfortunately, too many failed attempts for registration have occurred. Please try again later.")
     but: a string containing "DENY" was "{"transactionId":"4e087e65-77b9-4575-9965-afaaf214e968","output":{"advice":"ALLOW"}}"
at org.hamcrest.MatcherAssert.assertThat(MatcherAssert.java:20)
at org.junit.Assert.assertThat(Assert.java:956)
at org.junit.Assert.assertThat(Assert.java:923)
at TestNG.MFAC.AddressVelocity(MFAC.java:186)
at sun.reflect.NativeMethodAccessorImpl.invoke0(Native Method)
at sun.reflect.NativeMethodAccessorImpl.invoke(Unknown Source)
at sun.reflect.DelegatingMethodAccessorImpl.invoke(Unknown Source)
at java.lang.reflect.Method.invoke(Unknown Source)
at org.testng.internal.MethodInvocationHelper.invokeMethod(MethodInvocationHelper.java:124)
at org.testng.internal.Invoker.invokeMethod(Invoker.java:580)
at org.testng.internal.Invoker.invokeTestMethod(Invoker.java:716)
at org.testng.internal.TestMethodWithDataProviderMethodWorker.call(TestMethodWithDataProviderMethodWorker.java:71)
at org.testng.internal.TestMethodWithDataProviderMethodWorker.call(TestMethodWithDataProviderMethodWorker.java:14)
at java.util.concurrent.FutureTask.run(Unknown Source)
at java.util.concurrent.Executors$RunnableAdapter.call(Unknown Source)
at java.util.concurrent.FutureTask.run(Unknown Source)
at java.util.concurrent.ThreadPoolExecutor.runWorker(Unknown Source)
at java.util.concurrent.ThreadPoolExecutor$Worker.run(Unknown Source)
at java.lang.Thread.run(Unknown Source)
]]>
    </failure>
  </testcase> <!-- AddressVelocity -->
  <testcase name="IssuePinVelocity" time="9.518" classname="TestNG.MFAC"/>
  <testcase name="VerifyPinNoLongerValid" time="13.809" classname="TestNG.MFAC"/>
  <testcase name="IssuePin" time="2.245" classname="TestNG.MFAC"/>
  <testcase name="VerifyPinValid" time="6.420" classname="TestNG.MFAC"/>
  <testcase name="IssuePinVelocity" time="14.518" classname="TestNG.MFAC"/>
  <testcase name="IssuePinVelocity" time="13.918" classname="TestNG.MFAC"/>
  <testcase name="VerifyPinVelocity" time="18.881" classname="TestNG.MFAC"/>
  <testcase name="IssuePin" time="4.778" classname="TestNG.MFAC"/>
  <testcase name="VerifyPinVelocity" time="21.797" classname="TestNG.MFAC"/>
  <testcase name="VerifyPinValid" time="7.565" classname="TestNG.MFAC"/>
  <testcase name="VerifyPinValid" time="6.828" classname="TestNG.MFAC"/>
  <testcase name="AddressVelocity" time="28.568" classname="TestNG.MFAC">
    <failure type="java.lang.AssertionError" message="
Expected: (a string containing &quot;DENY&quot; and a string containing &quot;Unfortunately, too many failed attempts for registration have occurred. Please try again later.&quot;)
     but: a string containing &quot;DENY&quot; was &quot;{&quot;transactionId&quot;:&quot;7a776ee8-3c85-4194-9ffe-10231455880d&quot;,&quot;output&quot;:{&quot;advice&quot;:&quot;ALLOW&quot;}}&quot;">
      <![CDATA[java.lang.AssertionError: 
Expected: (a string containing "DENY" and a string containing "Unfortunately, too many failed attempts for registration have occurred. Please try again later.")
     but: a string containing "DENY" was "{"transactionId":"7a776ee8-3c85-4194-9ffe-10231455880d","output":{"advice":"ALLOW"}}"
at org.hamcrest.MatcherAssert.assertThat(MatcherAssert.java:20)
at org.junit.Assert.assertThat(Assert.java:956)
at org.junit.Assert.assertThat(Assert.java:923)
at TestNG.MFAC.AddressVelocity(MFAC.java:186)
at sun.reflect.NativeMethodAccessorImpl.invoke0(Native Method)
at sun.reflect.NativeMethodAccessorImpl.invoke(Unknown Source)
at sun.reflect.DelegatingMethodAccessorImpl.invoke(Unknown Source)
at java.lang.reflect.Method.invoke(Unknown Source)
at org.testng.internal.MethodInvocationHelper.invokeMethod(MethodInvocationHelper.java:124)
at org.testng.internal.Invoker.invokeMethod(Invoker.java:580)
at org.testng.internal.Invoker.invokeTestMethod(Invoker.java:716)
at org.testng.internal.TestMethodWithDataProviderMethodWorker.call(TestMethodWithDataProviderMethodWorker.java:71)
at org.testng.internal.TestMethodWithDataProviderMethodWorker.call(TestMethodWithDataProviderMethodWorker.java:14)
at java.util.concurrent.FutureTask.run(Unknown Source)
at java.util.concurrent.Executors$RunnableAdapter.call(Unknown Source)
at java.util.concurrent.FutureTask.run(Unknown Source)
at java.util.concurrent.ThreadPoolExecutor.runWorker(Unknown Source)
at java.util.concurrent.ThreadPoolExecutor$Worker.run(Unknown Source)
at java.lang.Thread.run(Unknown Source)
]]>
    </failure>
  </testcase> <!-- AddressVelocity -->
  <testcase name="AddressVelocity" time="26.354" classname="TestNG.MFAC">
    <failure type="java.lang.AssertionError" message="
Expected: (a string containing &quot;DENY&quot; and a string containing &quot;Unfortunately, too many failed attempts for registration have occurred. Please try again later.&quot;)
     but: a string containing &quot;DENY&quot; was &quot;{&quot;transactionId&quot;:&quot;070c4202-8db3-454d-b076-9185be72fe7c&quot;,&quot;output&quot;:{&quot;advice&quot;:&quot;ALLOW&quot;}}&quot;">
      <![CDATA[java.lang.AssertionError: 
Expected: (a string containing "DENY" and a string containing "Unfortunately, too many failed attempts for registration have occurred. Please try again later.")
     but: a string containing "DENY" was "{"transactionId":"070c4202-8db3-454d-b076-9185be72fe7c","output":{"advice":"ALLOW"}}"
at org.hamcrest.MatcherAssert.assertThat(MatcherAssert.java:20)
at org.junit.Assert.assertThat(Assert.java:956)
at org.junit.Assert.assertThat(Assert.java:923)
at TestNG.MFAC.AddressVelocity(MFAC.java:186)
at sun.reflect.NativeMethodAccessorImpl.invoke0(Native Method)
at sun.reflect.NativeMethodAccessorImpl.invoke(Unknown Source)
at sun.reflect.DelegatingMethodAccessorImpl.invoke(Unknown Source)
at java.lang.reflect.Method.invoke(Unknown Source)
at org.testng.internal.MethodInvocationHelper.invokeMethod(MethodInvocationHelper.java:124)
at org.testng.internal.Invoker.invokeMethod(Invoker.java:580)
at org.testng.internal.Invoker.invokeTestMethod(Invoker.java:716)
at org.testng.internal.TestMethodWithDataProviderMethodWorker.call(TestMethodWithDataProviderMethodWorker.java:71)
at org.testng.internal.TestMethodWithDataProviderMethodWorker.call(TestMethodWithDataProviderMethodWorker.java:14)
at java.util.concurrent.FutureTask.run(Unknown Source)
at java.util.concurrent.Executors$RunnableAdapter.call(Unknown Source)
at java.util.concurrent.FutureTask.run(Unknown Source)
at java.util.concurrent.ThreadPoolExecutor.runWorker(Unknown Source)
at java.util.concurrent.ThreadPoolExecutor$Worker.run(Unknown Source)
at java.lang.Thread.run(Unknown Source)
]]>
    </failure>
  </testcase> <!-- AddressVelocity -->
  <testcase name="VerifyPinNoLongerValid" time="10.595" classname="TestNG.MFAC"/>
  <testcase name="VerifyPinNoLongerValid" time="13.714" classname="TestNG.MFAC"/>
  <testcase name="VerifyPinVelocity" time="19.029" classname="TestNG.MFAC"/>
  <testcase name="IssuePinVelocity" time="12.001" classname="TestNG.MFAC">
    <failure type="java.lang.AssertionError" message="
Expected: (a string containing &quot;5700&quot; and a string containing &quot;Unfortunately, you have exceeded your attempts for verification. Please try again later.&quot;)
     but: a string containing &quot;5700&quot; was &quot;{&quot;transactionId&quot;:&quot;65ffa943-381b-4631-baea-175439a11704&quot;,&quot;output&quot;:{&quot;pinOTP&quot;:&quot;055645&quot;,&quot;pinExpirationDate&quot;:&quot;10/25/2018 06:43 PM GMT&quot;}}&quot;">
      <![CDATA[java.lang.AssertionError: 
Expected: (a string containing "5700" and a string containing "Unfortunately, you have exceeded your attempts for verification. Please try again later.")
     but: a string containing "5700" was "{"transactionId":"65ffa943-381b-4631-baea-175439a11704","output":{"pinOTP":"055645","pinExpirationDate":"10/25/2018 06:43 PM GMT"}}"
at org.hamcrest.MatcherAssert.assertThat(MatcherAssert.java:20)
at org.junit.Assert.assertThat(Assert.java:956)
at org.junit.Assert.assertThat(Assert.java:923)
at TestNG.MFAC.IssuePinVelocity(MFAC.java:224)
at sun.reflect.NativeMethodAccessorImpl.invoke0(Native Method)
at sun.reflect.NativeMethodAccessorImpl.invoke(Unknown Source)
at sun.reflect.DelegatingMethodAccessorImpl.invoke(Unknown Source)
at java.lang.reflect.Method.invoke(Unknown Source)
at org.testng.internal.MethodInvocationHelper.invokeMethod(MethodInvocationHelper.java:124)
at org.testng.internal.Invoker.invokeMethod(Invoker.java:580)
at org.testng.internal.Invoker.invokeTestMethod(Invoker.java:716)
at org.testng.internal.TestMethodWithDataProviderMethodWorker.call(TestMethodWithDataProviderMethodWorker.java:71)
at org.testng.internal.TestMethodWithDataProviderMethodWorker.call(TestMethodWithDataProviderMethodWorker.java:14)
at java.util.concurrent.FutureTask.run(Unknown Source)
at java.util.concurrent.Executors$RunnableAdapter.call(Unknown Source)
at java.util.concurrent.FutureTask.run(Unknown Source)
at java.util.concurrent.ThreadPoolExecutor.runWorker(Unknown Source)
at java.util.concurrent.ThreadPoolExecutor$Worker.run(Unknown Source)
at java.lang.Thread.run(Unknown Source)
]]>
    </failure>
  </testcase> <!-- IssuePinVelocity -->
  <testcase name="AddressVelocity" time="35.362" classname="TestNG.MFAC">
    <failure type="java.lang.AssertionError" message="
Expected: (a string containing &quot;DENY&quot; and a string containing &quot;Unfortunately, too many failed attempts for registration have occurred. Please try again later.&quot;)
     but: a string containing &quot;DENY&quot; was &quot;{&quot;transactionId&quot;:&quot;6ddf313c-0071-4ea3-bcc6-4904618b0adb&quot;,&quot;output&quot;:{&quot;advice&quot;:&quot;ALLOW&quot;}}&quot;">
      <![CDATA[java.lang.AssertionError: 
Expected: (a string containing "DENY" and a string containing "Unfortunately, too many failed attempts for registration have occurred. Please try again later.")
     but: a string containing "DENY" was "{"transactionId":"6ddf313c-0071-4ea3-bcc6-4904618b0adb","output":{"advice":"ALLOW"}}"
at org.hamcrest.MatcherAssert.assertThat(MatcherAssert.java:20)
at org.junit.Assert.assertThat(Assert.java:956)
at org.junit.Assert.assertThat(Assert.java:923)
at TestNG.MFAC.AddressVelocity(MFAC.java:186)
at sun.reflect.NativeMethodAccessorImpl.invoke0(Native Method)
at sun.reflect.NativeMethodAccessorImpl.invoke(Unknown Source)
at sun.reflect.DelegatingMethodAccessorImpl.invoke(Unknown Source)
at java.lang.reflect.Method.invoke(Unknown Source)
at org.testng.internal.MethodInvocationHelper.invokeMethod(MethodInvocationHelper.java:124)
at org.testng.internal.Invoker.invokeMethod(Invoker.java:580)
at org.testng.internal.Invoker.invokeTestMethod(Invoker.java:716)
at org.testng.internal.TestMethodWithDataProviderMethodWorker.call(TestMethodWithDataProviderMethodWorker.java:71)
at org.testng.internal.TestMethodWithDataProviderMethodWorker.call(TestMethodWithDataProviderMethodWorker.java:14)
at java.util.concurrent.FutureTask.run(Unknown Source)
at java.util.concurrent.Executors$RunnableAdapter.call(Unknown Source)
at java.util.concurrent.FutureTask.run(Unknown Source)
at java.util.concurrent.ThreadPoolExecutor.runWorker(Unknown Source)
at java.util.concurrent.ThreadPoolExecutor$Worker.run(Unknown Source)
at java.lang.Thread.run(Unknown Source)
]]>
    </failure>
  </testcase> <!-- AddressVelocity -->
  <testcase name="VerifyPinValid" time="7.485" classname="TestNG.MFAC"/>
  <testcase name="IssuePinExpiration" classname="TestNG.MFAC">
    <skipped/>
  </testcase> <!-- IssuePinExpiration -->
  <testcase name="AdditionalEnrollmentExpiration" classname="TestNG.MFAC">
    <skipped/>
  </testcase> <!-- AdditionalEnrollmentExpiration -->
  <testcase name="DetermineLockoutTime" classname="TestNG.MFAC">
    <skipped/>
  </testcase> <!-- DetermineLockoutTime -->
  <testcase name="AdditionalEnrollmentExpirationValidate" classname="TestNG.MFAC">
    <skipped/>
  </testcase> <!-- AdditionalEnrollmentExpirationValidate -->
  <testcase name="IssuePinExpirationValidate" classname="TestNG.MFAC">
    <skipped/>
  </testcase> <!-- IssuePinExpirationValidate -->
</testsuite> <!-- TestNG.MFAC -->
